<!-- ======================================================
	This file is part of MuJoCo.     
	Copyright 2009-2016 Roboti LLC.
	
	Model 		:: Baxter from rethink robotics
		Source		: 
		Downloaded	: 
		
	Mujoco		:: Advanced physics simulation engine
		Source		: www.roboti.us
		Version		: 1.31
		Released 	: 23Apr16
		
	Author		:: Vikash Kumar
		Contacts 	: kumar@roboti.us
		Last edits 	: 23May'16, 30Apr16, 26Sept'15, 26July'15

====================================================== -->

<mujoco model="baxter(v1.31)">
  <include file="../common/common_settings.xml"></include>
  <include file="../common/object_preloads.xml"></include>
  <include file="../common/paddle_preloads.xml"></include>
  <include file="../common/distract_preloads.xml"></include>
   <asset>
        <mesh name="base_link" file="torso/base_link.STL"/>
		<mesh name="base_link_collision" file="torso/base_link_collision.STL"/>
        <mesh name="PEDESTAL" file="base/PEDESTAL.STL"/>
		<mesh name="pedestal_link_collision" file="base/pedestal_link_collision.STL"/>
		<mesh name="H0" file="head/H0.STL"/>
		<mesh name="H1" file="head/H1.STL"/>
		<mesh name="S0" file="upper_shoulder/S0.STL"/>
		<mesh name="S1" file="lower_shoulder/S1.STL"/>
		<mesh name="E0" file="upper_elbow/E0.STL"/>
		<mesh name="E1" file="lower_elbow/E1.STL"/>
		<mesh name="W0" file="upper_forearm/W0.STL"/>
		<mesh name="W1" file="lower_forearm/W1.STL"/>
		<mesh name="W2" file="wrist/W2.STL"/>
		<mesh name="half_round_tip" file="electric_gripper/fingers/half_round_tip.STL" />
		<mesh name="electric_gripper_base" file="electric_gripper/electric_gripper_base.STL" />
        <mesh name="extended_narrow" file="electric_gripper/fingers/extended_narrow.STL"/>
        <mesh name="paddle_tip" file="electric_gripper/fingers/paddle_tip.STL"/>        
        <mesh name="paddle" file="paddle.STL"/>        

        <texture builtin="flat" name="floor_tex" height="32" width="32" rgb1="1 1 1" type="cube"></texture>
        <material name="floor_mat" shininess="0.03" specular="0.75" texture="floor_tex"></material>

        <texture builtin="flat" name="x_tex" height="32" width="32" rgb1="1 1 1" type="cube"></texture>
        <material name="x_mat" shininess="0.03" specular="0.75" texture="x_tex"></material>

        <texture builtin="flat" name="torso_tex" height="32" width="32" rgb1="1 1 1" type="cube"></texture>
        <material name="torso_mat" shininess="0.03" specular="0.75" texture="torso_tex"></material>

        <texture builtin="flat" name="pedestal_tex" height="32" width="32" rgb1="1 1 1" type="cube"></texture>
        <material name="pedestal_mat" shininess="0.03" specular="0.75" texture="pedestal_tex"></material>

        <texture builtin="flat" name="shoulder_tex" height="32" width="32" rgb1="1 1 1" type="cube"></texture>
        <material name="shoulder_mat" shininess="0.03" specular="0.75" texture="shoulder_tex"></material>

        <texture builtin="flat" name="screen_tex" height="32" width="32" rgb1="1 1 1" type="cube"></texture>
        <material name="screen_mat" shininess="0.03" specular="0.75" texture="screen_tex"></material>

        <texture builtin="flat" name="lower_should_tex" height="32" width="32" rgb1="1 1 1" type="cube"></texture>
        <material name="lower_should_mat" shininess="0.03" specular="0.75" texture="lower_should_tex"></material>

        <texture builtin="flat" name="head_tex" height="32" width="32" rgb1="1 1 1" type="cube"></texture>
        <material name="head_mat" shininess="0.03" specular="0.75" texture="head_tex"></material>

        <texture builtin="flat" name="wrist_tex" height="32" width="32" rgb1="1 1 1" type="cube"></texture>
        <material name="wrist_mat" shininess="0.03" specular="0.75" texture="wrist_tex"></material>

        <texture builtin="flat" name="gripper_tex" height="32" width="32" rgb1="1 1 1" type="cube"></texture>
        <material name="gripper_mat" shininess="0.03" specular="0.75" texture="gripper_tex"></material>

        <texture builtin="flat" name="hand_tex" height="32" width="32" rgb1="1 1 1" type="cube"></texture>
        <material name="hand_mat" shininess="0.03" specular="0.75" texture="hand_tex"></material>

        <texture builtin="flat" name="elbow_tex" height="32" width="32" rgb1="1 1 1" type="cube"></texture>
        <material name="elbow_mat" shininess="0.03" specular="0.75" texture="elbow_tex"></material>

        <texture builtin="flat" name="lower_elb_tex" height="32" width="32" rgb1="1 1 1" type="cube"></texture>
        <material name="lower_elb_mat" shininess="0.03" specular="0.75" texture="lower_elb_tex"></material>

        <texture builtin="flat" name="forearm_tex" height="32" width="32" rgb1="1 1 1" type="cube"></texture>
        <material name="forearm_mat" shininess="0.03" specular="0.75" texture="forearm_tex"></material>

        <texture builtin="flat" name="lower_fore_tex" height="32" width="32" rgb1="1 1 1" type="cube"></texture>
        <material name="lower_fore_mat" shininess="0.03" specular="0.75" texture="lower_fore_tex"></material>

        <texture builtin="flat" name="hand_paddle_tex" height="32" width="32" rgb1="1 1 1" type="cube"></texture>
        <material name="hand_paddle_mat" shininess="0.03" specular="0.75" texture="hand_paddle_tex"></material>
   </asset>
	
   <contact>       
        <exclude body1="right_upper_shoulder" body2="torso"/>
		<exclude body1="right_upper_shoulder" body2="right_upper_elbow"/>
		<exclude body1="right_lower_shoulder" body2="torso"/>

		<exclude body1="left_upper_shoulder" body2="torso"/>
		<exclude body1="left_upper_shoulder" body2="left_upper_elbow"/>
		<exclude body1="left_lower_shoulder" body2="torso"/>
		
		<exclude body1="collision_head_link_1" body2="torso"/>
		<exclude body1="collision_head_link_2" body2="torso"/>
        <!--
		<exclude body1="r_gripper_r_finger" body2="r_gripper_l_finger"/>
		<exclude body1="l_gripper_r_finger" body2="l_gripper_l_finger"/>
        -->
    </contact>



    <worldbody>
	    <camera name="camera1" pos="0.0 0.0 0.0" mode="fixed" target="object_table"/>
        <include file="../common/paddle_bodies.xml"></include>
        <include file="../common/object_bodies.xml"></include>
        <include file="../common/distract_bodies.xml"></include>

        <body name="base_ground" pos="0 0 -0.925">
        <geom name="ground" type="box" pos="0 0 -0.01" size="4 4 .01" rgba="0.7 0.6 0.5 1" material="floor_mat"/>
        <include file="../common/common_bodies_complex.xml"></include>
        <include file="../common/lights.xml"></include>
        <body name="base" pos="0 0 0.925" childclass="baxter_joint" quat="0 0 0 1">
            <inertial pos="0 0 0" mass="10" diaginertia="0.001 0.001 0.001" />
            <body name="collision_head_link_1" pos="0.11 0 0.75">
                <inertial pos="0 0 0" mass="0.0001" diaginertia="1e-008 1e-008 1e-008" />
                <geom type="sphere" class="viz" size="0.001" rgba="0.8 0.3 0.3 0.0" pos="0 0 0" material="x_mat" />
            </body>
            <body name="collision_head_link_2" pos="0.11 0 0.75">
                <inertial pos="0 0 0" mass="0.0001" diaginertia="1e-008 1e-008 1e-008" />
                <geom type="sphere" size="0.001" rgba="0.8 0.3 0.3 0.0" pos="0 0 0" material="x_mat" />
                <geom type="sphere" size="0.22" rgba="0.8 0.3 0.3 0.0" pos="-0.07 0.04 0" material="x_mat" />
            </body>
            <body name="torso" pos="0 0 0">
                <inertial pos="0 0 0" quat="0.997433 0.00167178 0.0715546 -0.00209003" mass="35.3365" diaginertia="1.87139 1.66268 0.779991" />
                <geom name="torso" class="viz" mesh="base_link" rgba="0.2 0.2 0.2 1" material="torso_mat"/>
                <!--<body name="left_torso_itb" pos="-0.08897 0.15593 0.389125" quat="3.2758e-005 -3.2758e-005 0.707107 0.707107">
                    <inertial pos="0 0 0" mass="0.0001" diaginertia="1e-008 1e-008 1e-008" />
                </body>
                <body name="right_torso_itb" pos="-0.08897 -0.15593 0.389125" quat="0.707107 0.707107 0 0">
                    <inertial pos="0 0 0" mass="0.0001" diaginertia="1e-008 1e-008 1e-008" />
                </body>-->
                <body name="pedestal" pos="0 0 0">
                    <inertial pos="0 0 0" quat="0.659267 -0.259505 -0.260945 0.655692" mass="60.864" diaginertia="6.0869 5.81635 4.20915" />
                    <geom name="pedestal" class="viz" rgba="0.2 0.2 0.2 1" mesh="PEDESTAL" material="pedestal_mat"/>
                </body>
                <body name="head" pos="0.06 0 0.686">
                    <inertial pos="0 0 0" quat="0.339345 0.850736 -0.347392 0.201027" mass="0.547767" diaginertia="0.00474065 0.00461087 0.00199949" />
                    <joint name="head_pan" type="hinge" pos="0 0 0" axis="0 0 1" range="-1.5708 1.5708"/> <!--maxvel="10000" />-->
                    <geom name="head" class="viz" rgba="0.2 0.2 0.2 1" mesh="H0" material="head_mat"/>
                    <body name="screen" pos="0.1227 0 0" quat="0.453099 0.542864 0.542864 0.453099">
                        <inertial pos="0 0 0" quat="0.995785 0.0113501 -0.000390852 0.0910132" mass="0.440171" diaginertia="0.0040484 0.00275826 0.00150834" />
                        <geom name="screen" class="viz" rgba="0.5 0.1 0.1 1" mesh="H1" pos="0 0 -.03" euler="0 -1.57 0" material="screen_mat"/>
						<geom name="display" class="viz" type="box" size="0.109 0.08 0.002" rgba=".9 .9 .9 1" pos="0 -0.016 0" quat="0.991445 0.130526 0 0" material="screen_mat"/>
                    </body>
                    <!--<body name="head_camera" pos="0.12839 0 0.06368" quat="0.453099 0.542864 0.542864 0.453099">
                        <inertial pos="0 0 0" mass="0.0001" diaginertia="1e-008 1e-008 1e-008" />
                    </body>-->
                </body>
                <!--<body name="sonar_ring" pos="0.0947 0 0.817">
                    <inertial pos="0 0 0" mass="0.0001" diaginertia="1e-008 1e-008 1e-008" />
                    <geom type="cylinder" class="viz" size="0.085 0.005" rgba="0.2 0.2 0.2 1" pos="-0.0347 0 0.00953"  material="ring_mat"/>
                    <geom type="sphere" size="0.001" rgba="0.2 0.2 0.2 1" pos="0 0 0"  material="ring_mat"/>
                </body>-->
				
				
                <body name="right_arm_mount" pos="0.024645 -0.219645 0.118588" quat="0.923879 0 0 -0.382684">
                    <inertial pos="0 0 0" mass="0.0001" diaginertia="1e-008 1e-008 1e-008" />
                    <body name="right_upper_shoulder" pos="0.055695 0 0.011038">
                        <inertial pos="0.01783 0.00086 0.19127" quat="0.975667 0.0673303 -0.206117 0.0325173" mass="5.70044" diaginertia="0.0498344 0.0377511 0.0331351" />
                        <joint name="right_s0" type="hinge" pos="0 0 0" axis="0 0 1" range="-1.70168 1.70168"/><!-- maxvel="1.5" />-->
                        <geom name="right_upper_shoulder" class="viz" rgba="0.5 0.1 0.1 1" mesh="S0" material="shoulder_mat"/>
                        <body name="right_lower_shoulder" pos="0.069 0 0.27035" quat="0.707107 -0.707107 0 0">
                            <inertial pos="0.06845 0.00269 -0.00529" quat="0.447487 0.536948 0.56425 0.439391" mass="3.22698" diaginertia="0.0278991 0.0212327 0.0112937" />
                            <joint name="right_s1" type="hinge" pos="0 0 0" axis="0 0 1" range="-2.147 1.047"/><!-- maxvel="1.5" />-->
                            <geom name="right_lower_shoulder" class="viz" rgba="0.5 0.1 0.1 1" mesh="S1" material="lower_should_mat"/>
                            <body name="right_upper_elbow" pos="0.102 0 0" quat="0.5 0.5 0.5 0.5">
                                <inertial pos="-0.00276 0.00132 0.18086" quat="0.838995 -0.0423128 -0.121287 0.52876" mass="4.31272" diaginertia="0.0287695 0.0273625 0.011409" />
                                <joint name="right_e0" type="hinge" pos="0 0 0" axis="0 0 1" range="-3.05418 3.05418"/><!-- maxvel="1.5" />-->
                                <geom name="right_upper_elbow" class="viz" rgba="0.5 0.1 0.1 1" mesh="E0" material="elbow_mat"/>
                                <!-->
								<geom name="right_upper_elbow_visual" type="cylinder" size="0.06 0.1365" pos="0 0 0.1365"  material="elbow_mat"/>
                                -->
                                <body name="right_lower_elbow" pos="0.069 0 0.26242" quat="0.5 -0.5 -0.5 -0.5">
                                    <inertial pos="0.02611 0.00159 -0.01117" quat="0.440433 0.577149 0.562777 0.395221" mass="2.07206" diaginertia="0.0132096 0.00950002 0.00685697" />
                                    <joint name="right_e1" type="hinge" pos="0 0 0" axis="0 0 1" range="-0.05 2.618"/><!-- maxvel="1.5" />-->
                                    <geom name="right_lower_elbow" class="viz" rgba="0.5 0.1 0.1 1" mesh="E1" material="lower_elb_mat"/>
                                    <body name="right_upper_forearm" pos="0.10359 0 0" quat="0.5 0.5 0.5 0.5">
                                        <inertial pos="-0.00168 0.0046 0.13952" quat="0.892709 -0.0256256 0.00446984 0.449882" mass="2.24665" diaginertia="0.016916 0.0165511 0.00371123" />
                                        <joint name="right_w0" type="hinge" pos="0 0 0" axis="0 0 1" range="-3.059 3.059"/><!-- maxvel="4" />-->
                                        <geom name="right_upper_forearm" class="viz" rgba="0.5 0.1 0.1 1" mesh="W0" material="forearm_mat"/>
										<geom name="right_upper_forearm_visual" type="cylinder" size="0.06 0.1036" pos="0 0 0.1"  material="forearm_mat"/>
                                        <!--<body name="right_arm_itb" pos="-0.0565 0 0.12" quat="0.5 -0.5 -0.5 0.5">
                                            <inertial pos="0 0 0" mass="0.0001" diaginertia="1e-008 1e-008 1e-008" />
                                        </body>-->
                                        <body name="right_lower_forearm" pos="0.01 0 0.2707" quat="0.5 -0.5 -0.5 -0.5">
                                            <inertial pos="0.06041 0.00697 0.006" quat="0.456911 0.468526 0.475683 0.587743" mass="1.60979" diaginertia="0.00708828 0.00552689 0.00379383" />
                                            <joint name="right_w1" type="hinge" pos="0 0 0" axis="0 0 1" range="-1.5708 2.094"/><!-- maxvel="4" />-->
                                            <geom name="right_lower_forearm" class="viz" rgba="0.5 0.1 0.1 1" mesh="W1" material="lower_fore_mat"/>
                                            <body name="right_wrist" pos="0.115975 0 0" quat="0.5 0.5 0.5 0.5">
                                                <inertial pos="0.00198 0.00125 0.01855" quat="0.0594843 0.68926 -0.16016 0.704082" mass="0.35093" diaginertia="0.0003082 0.000269928 0.000251035" />
                                                <joint name="right_w2" type="hinge" pos="0 0 0" axis="0 0 1" range="-3.059 3.059"/><!-- maxvel="4" />-->
                                                <geom name="right_wrist" class="viz" rgba="0.1 0.1 0.1 1" mesh="W2" material="wrist_mat"/>
                                                <body name="right_hand" pos="0 0 0.11355">
                                                    <inertial pos="0.01093 0.00042 -0.01532" quat="0.025365 0.814618 0.0196357 0.579109" mass="0.19125" diaginertia="0.000246058 0.000211549 0.000167391" />
                                                    <geom name="right_hand" type="cylinder" size="0.04 0.0232" pos="0 0 -0.0232"  material="hand_mat"/>

                                                    <body name="right_paddle" pos="-0.07 -0.01 0.02">
                                                        <inertial pos="0 0 0" mass="0.19125" diaginertia="1e-8 1e-8 1e-8" />
                                                        <geom name="right_paddle" class="viz" mesh="paddle" material="hand_paddle_mat" euler="0 0 -0.785398"  />
                                                    </body>

                                                    <!--<body name="right_hand_camera" pos="0.03825 0.012 0.015355" quat="0.707107 0 0 -0.707107">
                                                        <inertial pos="0 0 0" mass="0.0001" diaginertia="1e-008 1e-008 1e-008" />
                                                        <geom type="cylinder" class="viz" size="0.02 0.005" rgba="0 0 1 0.8" pos="0 0 0"  material="hand_mat"/>
                                                    </body>
                                                    <body name="right_hand_camera_axis" pos="0.03825 0.012 0.015355">
                                                        <inertial pos="0 0 0" mass="0.0001" diaginertia="1e-008 1e-008 1e-008" />
                                                    </body>
                                                    <body name="right_hand_range" pos="0.032 -0.020245 0.0288" quat="0.5 -0.5 -0.5 -0.5">
                                                        <inertial pos="0 0 0" mass="0.0001" diaginertia="1e-008 1e-008 1e-008" />
                                                        <geom type="box" class="viz" size="0.0025 0.01 0.0025" rgba="0 0 1 0.8" pos="0 0 0"  material="hand_mat"/>
                                                    </body>
                                                    <body name="right_hand_accelerometer" pos="0.00198 0.000133 -0.0146">
                                                        <inertial pos="0 0 0" mass="0.0001" diaginertia="1e-008 1e-008 1e-008" />
                                                        <geom type="box" class="viz" size="0.005 0.005 0.005" rgba="0 0 0 1" pos="0 0 0"  material="hand_mat"/>
                                                    </body>-->
                                                    <!--
                                                    <body name="right_gripper_base" pos="0 0 0.025">
                                                        <inertial pos="0 0 0" quat="-0.5 0.5 0.5 0.5" mass="0.3" diaginertia="3e-08 2e-08 2e-08" />
                                                        <geom name="right_gripper_base" quat="0 0 0.707107 0.707107" class="viz" mesh="electric_gripper_base"  material="gripper_mat"/>
                                                        <body name="r_gripper_l_finger" pos="0 -0.0015 0.02">
                                                            <inertial pos="0 0 0" quat="0 0 0 -1" mass="0.02" diaginertia="0.01 0.01 0.01" />
                                                            <joint name="r_gripper_l_finger_joint" pos="0 0 0" axis="0 1 0" type="slide" range="0 0.020833" />
                                                            <geom name="r_gripper_l_finger" class="viz" mesh="extended_narrow" euler="1.57 1.57 0" rgba="0.1 0.1 0.1 1" material="gripper_mat"/>
                                                            <body name="r_gripper_l_finger_tip" pos="0 0.01725 0.1127">
                                                                <inertial pos="0 0 0" quat="0 0 0 1" mass="0.01" diaginertia="0.01 0.01 0.01" />
                                                                <geom name="r_gripper_l_finger_tip" pos="-.007 -.01 0.003" class="viz" mesh="half_round_tip" euler="-1.57 0 0" material="gripper_mat"/>
                                                            </body>
                                                        </body>
                                                        <body name="r_gripper_r_finger" pos="0 0.0015 0.02">
                                                            <inertial pos="0 0 0" mass="0.02" diaginertia="0.01 0.01 0.01" />
                                                            <joint name="r_gripper_r_finger_joint" pos="0 0 0" axis="0 1 0" type="slide" range="-0.020833 0" />
                                                            <geom name="r_gripper_r_finger" class="viz" mesh="extended_narrow" euler="1.57 -1.57 0" rgba="0.1 0.1 0.1 1" material="gripper_mat"/>
                                                            <body name="r_gripper_r_finger_tip" pos="0 -0.01725 0.1127">
                                                                <inertial pos="0 0 0" mass="0.01" diaginertia="0.01 0.01 0.01" />
                                                                <geom name="r_gripper_r_finger_tip" pos=".007 .01 0.003" class="viz" mesh="half_round_tip" euler="-1.57 3.14 0" material="gripper_mat"/>
                                                            </body>
                                                        </body>
                                                    </body>
                                                    -->
                                                </body>
                                            </body>
                                        </body>
                                    </body>
                                </body>
                            </body>
                        </body>
                    </body>
                </body>
                <body name="left_arm_mount" pos="0.024645 0.219645 0.118588" quat="0.923879 0 0 0.382684">
                    <inertial pos="0 0 0" mass="0.0001" diaginertia="1e-008 1e-008 1e-008" />
                    <body name="left_upper_shoulder" pos="0.055695 0 0.011038">
                        <inertial pos="0.01783 0.00086 0.19127" quat="0.975667 0.0673303 -0.206117 0.0325173" mass="5.70044" diaginertia="0.0498344 0.0377511 0.0331351" />
                        <joint name="left_s0" type="hinge" pos="0 0 0" axis="0 0 1" range="-1.70168 1.70168"/><!-- maxvel="1.5" />-->
                        <geom name="left_upper_shoulder" class="viz" rgba="0.5 0.1 0.1 1" mesh="S0" material="shoulder_mat"/>
                        <body name="left_lower_shoulder" pos="0.069 0 0.27035" quat="0.707107 -0.707107 0 0">
                            <inertial pos="0.06845 0.00269 -0.00529" quat="0.447487 0.536948 0.56425 0.439391" mass="3.22698" diaginertia="0.0278991 0.0212327 0.0112937" />
                            <joint name="left_s1" type="hinge" pos="0 0 0" axis="0 0 1" range="-2.147 1.047"/><!-- maxvel="1.5" />-->
                            <geom name="left_lower_shoulder" class="viz" rgba="0.5 0.1 0.1 1" mesh="S1" material="lower_should_mat"/>
                            <body name="left_upper_elbow" pos="0.102 0 0" quat="0.5 0.5 0.5 0.5">
                                <inertial pos="-0.00276 0.00132 0.18086" quat="0.838995 -0.0423128 -0.121287 0.52876" mass="4.31272" diaginertia="0.0287695 0.0273625 0.011409" />
                                <joint name="left_e0" type="hinge" pos="0 0 0" axis="0 0 1" range="-3.05418 3.05418"/><!-- maxvel="1.5" />-->
                                <geom name="left_upper_elbow" class="viz" rgba="0.5 0.1 0.1 1" mesh="E0" material="elbow_mat"/>
								
								<body name="left_lower_elbow" pos="0.069 0 0.26242" quat="0.5 -0.5 -0.5 -0.5">
                                    <inertial pos="0.02611 0.00159 -0.01117" quat="0.440433 0.577149 0.562777 0.395221" mass="2.07206" diaginertia="0.0132096 0.00950002 0.00685697" />
                                    <joint name="left_e1" type="hinge" pos="0 0 0" axis="0 0 1" range="-0.05 2.618"/><!-- maxvel="1.5" />-->
                                    <geom name="left_lower_elbow" class="viz" rgba="0.5 0.1 0.1 1" mesh="E1" material="lower_elb_mat"/>
                                    <body name="left_upper_forearm" pos="0.10359 0 0" quat="0.5 0.5 0.5 0.5">
                                        <inertial pos="-0.00168 0.0046 0.13952" quat="0.892709 -0.0256256 0.00446984 0.449882" mass="2.24665" diaginertia="0.016916 0.0165511 0.00371123" />
                                        <joint name="left_w0" type="hinge" pos="0 0 0" axis="0 0 1" range="-3.059 3.059"/><!-- maxvel="4" />-->
                                        <geom name="left_upper_forearm" class="viz" rgba="0.5 0.1 0.1 1" mesh="W0" material="forearm_mat"/>

                                        <!--<body name="left_arm_itb" pos="-0.0565 0 0.12" quat="0.5 -0.5 -0.5 0.5">
                                            <inertial pos="0 0 0" mass="0.0001" diaginertia="1e-008 1e-008 1e-008" />
                                        </body>-->
                                        <body name="left_lower_forearm" pos="0.01 0 0.2707" quat="0.5 -0.5 -0.5 -0.5">
                                            <inertial pos="0.06041 0.00697 0.006" quat="0.456911 0.468526 0.475683 0.587743" mass="1.60979" diaginertia="0.00708828 0.00552689 0.00379383" />
                                            <joint name="left_w1" type="hinge" pos="0 0 0" axis="0 0 1" range="-1.5708 2.094"/><!-- maxvel="4" />-->
                                            <geom name="left_lower_forearm" class="viz" rgba="0.5 0.1 0.1 1" mesh="W1" material="lower_fore_mat"/>
                                            <body name="left_wrist" pos="0.115975 0 0" quat="0.5 0.5 0.5 0.5">
                                                <inertial pos="0.00198 0.00125 0.01855" quat="0.0594843 0.68926 -0.16016 0.704082" mass="0.35093" diaginertia="0.0003082 0.000269928 0.000251035" />
                                                <joint name="left_w2" type="hinge" pos="0 0 0" axis="0 0 1" range="-3.059 3.059"/><!-- maxvel="4" />-->
                                                <geom name="left_wrist" class="viz" rgba="0.1 0.1 0.1 1" mesh="W2" material="wrist_mat"/>
                                                <body name="left_hand" pos="0 0 0.11355">
                                                    <inertial pos="0.01093 0.00042 -0.01532" quat="0.025365 0.814618 0.0196357 0.579109" mass="0.19125" diaginertia="0.000246058 0.000211549 0.000167391" />
                                                    <geom name="left_hand" type="cylinder" size="0.04 0.0232" pos="0 0 -0.0232"  material="hand_mat"/>
                                                    <body name="left_paddle" pos="0.0 -0.06 0.02">
                                                        <inertial pos="0 0 0" mass="0.19125" diaginertia="1e-8 1e-8 1e-8" />
                                                        <geom name="left_paddle" class="viz" mesh="paddle" material="hand_paddle_mat" euler="0 0 0.785398"  />
                                                    </body>
                                                    <!--<body name="left_hand_camera" pos="0.03825 0.012 0.015355" quat="0.707107 0 0 -0.707107">
                                                        <inertial pos="0 0 0" mass="0.0001" diaginertia="1e-008 1e-008 1e-008" />
                                                        <geom type="cylinder" class="viz" size="0.02 0.005" rgba="0 0 1 0.8" pos="0 0 0"  material="hand_mat"/>
                                                    </body>
                                                    <body name="left_hand_camera_axis" pos="0.03825 0.012 0.015355">
                                                        <inertial pos="0 0 0" mass="0.0001" diaginertia="1e-008 1e-008 1e-008" />
                                                    </body>
                                                    <body name="left_hand_range" pos="0.032 -0.020245 0.0288" quat="0.5 -0.5 -0.5 -0.5">
                                                        <inertial pos="0 0 0" mass="0.0001" diaginertia="1e-008 1e-008 1e-008" />
                                                        <geom type="box" class="viz" size="0.0025 0.01 0.0025" rgba="0 0 1 0.8" pos="0 0 0"  material="hand_mat"/>
                                                    </body>
                                                    <body name="left_hand_accelerometer" pos="0.00198 0.000133 -0.0146">
                                                        <inertial pos="0 0 0" mass="0.0001" diaginertia="1e-008 1e-008 1e-008" />
                                                        <geom type="box" class="viz" size="0.005 0.005 0.005" rgba="0 0 0 1" pos="0 0 0"  material="hand_mat"/>
                                                    </body>-->
                                                    <!--
                                                    <body name="left_gripper_base" pos="0 0 0.025">
                                                        <inertial pos="0 0 0" quat="-0.5 0.5 0.5 0.5" mass="0.3" diaginertia="3e-08 2e-08 2e-08" />
                                                        <geom name="left_gripper_base" quat="0 0 0.707107 0.707107" class="viz" mesh="electric_gripper_base"  material="gripper_mat"/>
                                                        <body name="l_gripper_l_finger" pos="0 -0.0015 0.02">
                                                            <inertial pos="0 0 0" quat="0 0 0 -1" mass="0.02" diaginertia="0.01 0.01 0.01" />
                                                            <joint name="l_gripper_l_finger_joint" pos="0 0 0" axis="0 1 0" type="slide" range="0 0.020833" />
                                                            <geom name="left_gripper" class="viz" mesh="extended_narrow" euler="1.57 1.57 0" rgba="0.1 0.1 0.1 1" material="gripper_mat"/>
                                                            <body name="l_gripper_l_finger_tip" pos="0 0.01725 0.1127">
                                                                <inertial pos="0 0 0" quat="0 0 0 1" mass="0.01" diaginertia="0.01 0.01 0.01" />
                                                                <geom name="l_gripper_l_finger_tip" class="viz" pos="-.02 -.009 0.003" mesh="paddle_tip" euler="-1.57 0 0" material="gripper_mat"/>
                                                            </body>
                                                        </body>
                                                         <body name="l_gripper_r_finger" pos="0 0.0015 0.02">
                                                            <inertial pos="0 0 0" mass="0.02" diaginertia="0.01 0.01 0.01" />
                                                            <joint name="l_gripper_r_finger_joint" pos="0 0 0" axis="0 1 0" type="slide" range="-0.020833 0" />
                                                            <geom name="l_gripper_r_finger" class="viz" mesh="extended_narrow" euler="1.57 -1.57 0" rgba="0.1 0.1 0.1 1" material="gripper_mat"/>
                                                            <body name="l_gripper_r_finger_tip" pos="0 -0.01725 0.1127">
                                                                <inertial pos="0 0 0" mass="0.01" diaginertia="0.01 0.01 0.01" />
                                                                <geom name="l_gripper_r_finger_tip" pos=".02 .009 0.003" class="viz" mesh="paddle_tip" euler="-1.57 3.14 0" material="gripper_mat"/>
                                                            </body>
                                                        </body> 
                                                    </body>
                                                    -->
                                                </body>
                                            </body>
                                        </body>
                                    </body>
                                </body>
                            </body>
                        </body>
                    </body>
                </body>
            </body>
        </body>
        </body>
    </worldbody>
</mujoco>
